<?xml version="1.0" encoding="UTF-8"?>
<robot xmlns:xacro="http://ros.org/wiki/xacro">
  <xacro:include filename="$(find abb_resources)/urdf/common_materials.xacro"/>

  <xacro:macro name="abb_irb2600_12_165" params="prefix">

    <!-- links -->
    
    <link name="${prefix}base_link">
      <visual>
        <origin xyz="0 0 0" rpy="0 0 0" />
        <geometry>
          <mesh filename="package://abb_irb2600_gazebo_support/meshes/irb2600_12_165/visual/base_link.stl" />
        </geometry>
        <xacro:material_abb_orange/>
      </visual>
      <collision>
        <origin xyz="0 0 0" rpy="0 0 0" />
        <geometry>
          <mesh filename="package://abb_irb2600_gazebo_support/meshes/irb2600_12_165/collision/base_link.stl" />
        </geometry>
      </collision>
      <inertial>
        <origin rpy="0 0 0" xyz="-0.090268 0.004629 0.097232" />
        <mass value="50" />
        <inertia ixx="1.32353229329" ixy="0" ixz="0" iyy="2.12285787096" iyz="0" izz="3.00555681493" />
      </inertial>
    </link>
    
    <link name="${prefix}link_1">
      <visual>
        <origin xyz="0 0 0" rpy="0 0 0" />
        <geometry>
          <mesh filename="package://abb_irb2600_gazebo_support/meshes/irb2600_12_165/visual/link_1.stl" />
        </geometry>
        <xacro:material_abb_orange/>
      </visual>
      <collision>
        <origin xyz="0 0 0" rpy="0 0 0" />
        <geometry>
          <mesh filename="package://abb_irb2600_gazebo_support/meshes/irb2600_12_165/collision/link_1.stl" />
        </geometry>
      </collision>
      <inertial>
        <origin rpy="0 0 0" xyz="0.041781 0.007613 -0.057644" />
        <mass value="40" />
        <inertia ixx="1.3056356199" ixy="0" ixz="0" iyy="1.49822762385" iyz="0" izz="1.42975660018" />
      </inertial>
    </link>
    
    <link name="${prefix}link_2">
      <visual>
        <origin xyz="0 0 0" rpy="0 0 0" />
        <geometry>
          <mesh filename="package://abb_irb2600_gazebo_support/meshes/irb2600_12_165/visual/link_2.stl" />
        </geometry>
        <xacro:material_abb_orange/>
      </visual>
      <collision>
        <origin xyz="0 0 0" rpy="0 0 0" />
        <geometry>
          <mesh filename="package://abb_irb2600_gazebo_support/meshes/irb2600_12_165/collision/link_2.stl" />
        </geometry>
      </collision>
      <inertial>
        <origin rpy="0 0 0" xyz="0.000144 -0.172541 0.320995" />
        <mass value="25" />
        <inertia ixx="1.62299042151" ixy="0" ixz="0" iyy="1.65934561982" iyz="0" izz="0.130105205764" />
      </inertial>
    </link>
    
    <link name="${prefix}link_3">
      <visual>
        <origin xyz="0 0 0" rpy="0 0 0" />
        <geometry>
          <mesh filename="package://abb_irb2600_gazebo_support/meshes/irb2600_12_165/visual/link_3.stl" />
        </geometry>
        <xacro:material_abb_orange/>
      </visual>
      <collision>
        <origin xyz="0 0 0" rpy="0 0 0" />
        <geometry>
          <mesh filename="package://abb_irb2600_gazebo_support/meshes/irb2600_12_165/collision/link_3.stl" />
        </geometry>
      </collision>
      <inertial>
        <origin rpy="0 0 0" xyz="0.044120 0.013987 0.074494" />
        <mass value="35" />
        <inertia ixx="0.697962394843" ixy="0" ixz="0" iyy="0.935052636164" iyz="0" izz="0.914062497892" />
      </inertial>
    </link>
    
    <link name="${prefix}link_4">
      <visual>
        <origin xyz="0 0 0" rpy="0 0 0" />
        <geometry>
          <mesh filename="package://abb_irb2600_gazebo_support/meshes/irb2600_12_165/visual/link_4.stl" />
        </geometry>
        <xacro:material_abb_orange/>
      </visual>
      <collision>
        <origin xyz="0 0 0" rpy="0 0 0" />
        <geometry>
          <mesh filename="package://abb_irb2600_gazebo_support/meshes/irb2600_12_165/collision/link_4.stl" />
        </geometry>
      </collision>
      <inertial>
        <origin rpy="0 0 0" xyz="0.604117 0.001220 0.000333" />
        <mass value="40" />
        <inertia ixx="0.170804534384" ixy="0" ixz="0" iyy="1.21330463959" iyz="0" izz="1.22731510997" />
      </inertial>
    </link>
    
    <link name="${prefix}link_5">
      <visual>
        <origin xyz="0 0 0" rpy="0 0 0" />
        <geometry>
          <mesh filename="package://abb_irb2600_gazebo_support/meshes/irb2600_12_165/visual/link_5.stl" />
        </geometry>
        <xacro:material_abb_orange/>
      </visual>
      <collision>
        <origin xyz="0 0 0" rpy="0 0 0" />
        <geometry>
          <mesh filename="package://abb_irb2600_gazebo_support/meshes/irb2600_12_165/collision/link_5.stl" />
        </geometry>
      </collision>
      <inertial>
        <origin rpy="0 0 0" xyz="0.000235 -0.000022 0.000891" />
        <mass value="6" />
        <inertia ixx="0.00740707353269" ixy="0" ixz="0" iyy="0.0131331538032" iyz="0" izz="0.00740708036338" />
      </inertial>
    </link>
    
    <link name="${prefix}link_6">
      <visual>
        <origin xyz="0 0 0" rpy="0 0 0" />
        <geometry>
          <mesh filename="package://abb_irb2600_gazebo_support/meshes/irb2600_12_165/visual/link_6.stl" />
        </geometry>
        <material name="">
          <color rgba="0.5 0.5 0.5 1" />
        </material>
      </visual>
      <collision>
        <origin xyz="0 0 0" rpy="0 0 0" />
        <geometry>
          <mesh filename="package://abb_irb2600_gazebo_support/meshes/irb2600_12_165/collision/link_6.stl" />
        </geometry>
      </collision>
      <inertial>
        <origin rpy="0 0 0" xyz="-0.010849 0.000185 -0.000736" />
        <mass value="4" />
        <inertia ixx="0.0026450608523" ixy="0" ixz="0" iyy="0.00170833134651" iyz="0" izz="0.00170739524294" />
      </inertial>
    </link>

    <!-- Joints -->
    
    <joint name="${prefix}joint_1" type="revolute">
      <origin xyz="0 0 0.445" rpy="0 0 0" />
      <parent link="${prefix}base_link" />
      <child link="${prefix}link_1" />
      <axis xyz="0 0 1" />
      <limit lower="-3.14159" upper="3.14159" effort="0" velocity="3.054" />
    </joint>
    
    <joint name="${prefix}joint_2" type="revolute">
      <origin xyz="0.15 0 0.0" rpy="0 0 0" />
      <parent link="${prefix}link_1" />
      <child link="${prefix}link_2" />
      <axis xyz="0 1 0" />
      <limit lower="-2.705" upper="1.658" effort="0" velocity="3.054" />
    </joint>
    
    <joint name="${prefix}joint_3" type="revolute">
      <origin xyz="0 0 0.7" rpy="0 0 0" />
      <parent link="${prefix}link_2" />
      <child link="${prefix}link_3" />
      <axis xyz="0 1 0" />
      <limit lower="-2.705" upper="1.309" effort="0" velocity="3.054" />
    </joint>
    
    <joint name="${prefix}joint_4" type="revolute">
      <origin xyz="0 0 0.115" rpy="0 0 0" />
      <parent link="${prefix}link_3" />
      <child link="${prefix}link_4" />
      <axis xyz="1 0 0" />
      <limit lower="-6.981" upper="6.981" effort="0" velocity="6.283" />
    </joint>
    
    <joint name="${prefix}joint_5" type="revolute">
      <origin xyz="0.795 0 0 " rpy="0 0 0" />
      <parent link="${prefix}link_4" />
      <child link="${prefix}link_5" />
      <axis xyz="0 1 0" />
      <limit lower="-2.094" upper="2.094" effort="0" velocity="6.283" />
    </joint>
    
    <joint name="${prefix}joint_6" type="revolute">
      <origin xyz="0.085 0 0" rpy="0 0 0" />
      <parent link="${prefix}link_5" />
      <child link="${prefix}link_6" />
      <axis xyz="1 0 0" />
      <limit lower="-6.981" upper="6.981" effort="0" velocity="8.727" />
    </joint>

    <!-- ROS-Industrial 'base' frame: base_link to ABB World Coordinates transform -->
    
    <link name="${prefix}base" />
    
    <joint name="${prefix}base_link-base" type="fixed">
      <origin xyz="0 0 0" rpy="0 0 0"/>
      <parent link="${prefix}base_link"/>
      <child link="${prefix}base"/>
    </joint>

    <!-- ROS-Industrial 'flange' frame: attachment point for EEF models -->
    
    <link name="${prefix}flange"/>

    <joint type="fixed" name="${prefix}joint_6-flange">
      <origin xyz="0 0 0" rpy="0 0 0"/>
      <parent link="${prefix}link_6"/>
      <child link="${prefix}flange"/>
    </joint>

    <!-- ROS-Industrial 'tool0' frame: all-zeros tool frame -->
    
    <link name="${prefix}tool0" />
    
    <joint name="${prefix}link_6-tool0" type="fixed">
      <origin xyz="0 0 0" rpy="0 ${radians(90)} 0" />
      <parent link="${prefix}flange" />
      <child link="${prefix}tool0" />
    </joint>
  </xacro:macro>
</robot>
