<sdf version='1.7'>
  <model name='abb_irb2600_12_165_gazebo'>
    <link name='base_link'>
      <pose>0 0 0 0 -0 0</pose>
      <inertial>
        <pose>-0.090268 0.004629 0.097232 0 -0 0</pose>
        <mass>49</mass>
        <inertia>
          <ixx>0.000373321</ixx>
          <ixy>1.49951e-05</ixy>
          <ixz>2.122e-05</ixz>
          <iyy>0.000866269</iyy>
          <iyz>2.2766e-07</iyz>
          <izz>0.00105702</izz>
        </inertia>
      </inertial>
      <collision name='base_link_collision'>
        <pose>0 0 0 0 -0 0</pose>
        <geometry>
          <mesh>
            <scale>1 1 1</scale>
            <uri>model://abb_irb2600_gazebo_support/meshes/irb2600_12_165/collision/base_link.stl</uri>
          </mesh>
        </geometry>
        <surface>
          <contact>
            <ode/>
          </contact>
          <friction>
            <ode/>
          </friction>
        </surface>
      </collision>
      <visual name='base_link_visual'>
        <pose>0 0 0 0 -0 0</pose>
        <geometry>
          <mesh>
            <scale>1 1 1</scale>
            <uri>model://abb_irb2600_gazebo_support/meshes/irb2600_12_165/visual/base_link.stl</uri>
          </mesh>
        </geometry>
      </visual>
      <gravity>0</gravity>
      <velocity_decay/>
    </link>
    <joint name='world_to_base_link_joint' type='fixed'>
      <child>base_link</child>
      <parent>world</parent>
    </joint>
    <link name='link_1'>
      <pose>0 0 0.445 0 -0 0</pose>
      <inertial>
        <pose>0.041781 0.007613 -0.057644 0 -0 0</pose>
        <mass>38</mass>
        <inertia>
          <ixx>0.000387</ixx>
          <ixy>-1.1e-05</ixy>
          <ixz>-3.7e-05</ixz>
          <iyy>0.000593</iyy>
          <iyz>-8e-06</iyz>
          <izz>0.000569</izz>
        </inertia>
      </inertial>
      <collision name='link_1_collision'>
        <pose>0 0 0 0 -0 0</pose>
        <geometry>
          <mesh>
            <scale>1 1 1</scale>
            <uri>model://abb_irb2600_gazebo_support/meshes/irb2600_12_165/collision/link_1.stl</uri>
          </mesh>
        </geometry>
        <surface>
          <contact>
            <ode/>
          </contact>
          <friction>
            <ode/>
          </friction>
        </surface>
      </collision>
      <visual name='link_1_visual'>
        <pose>0 0 0 0 -0 0</pose>
        <geometry>
          <mesh>
            <scale>1 1 1</scale>
            <uri>model://abb_irb2600_gazebo_support/meshes/irb2600_12_165/visual/link_1.stl</uri>
          </mesh>
        </geometry>
      </visual>
      <gravity>0</gravity>
      <velocity_decay/>
    </link>
    <joint name='joint_1' type='revolute'>
      <child>link_1</child>
      <parent>base_link</parent>
      <axis>
        <xyz>0 0 1</xyz>
        <limit>
          <lower>-3.14159</lower>
          <upper>3.14159</upper>
          <effort>0</effort>
          <velocity>3.054</velocity>
        </limit>
        <dynamics>
          <spring_reference>0</spring_reference>
          <spring_stiffness>0</spring_stiffness>
        </dynamics>
      </axis>
    </joint>
    <link name='link_2'>
      <pose>0.15 0 0.445 0 -0 0</pose>
      <inertial>
        <pose>0.000144 -0.172541 0.320995 0 -0 0</pose>
        <mass>20</mass>
        <inertia>
          <ixx>0.000542328</ixx>
          <ixy>-2.36e-09</ixy>
          <ixz>1.6864e-07</ixz>
          <iyy>0.000557743</iyy>
          <iyz>3.21592e-06</iyz>
          <izz>3.21592e-06</izz>
        </inertia>
      </inertial>
      <collision name='link_2_collision'>
        <pose>0 0 0 0 -0 0</pose>
        <geometry>
          <mesh>
            <scale>1 1 1</scale>
            <uri>model://abb_irb2600_gazebo_support/meshes/irb2600_12_165/collision/link_2.stl</uri>
          </mesh>
        </geometry>
        <surface>
          <contact>
            <ode/>
          </contact>
          <friction>
            <ode/>
          </friction>
        </surface>
      </collision>
      <visual name='link_2_visual'>
        <pose>0 0 0 0 -0 0</pose>
        <geometry>
          <mesh>
            <scale>1 1 1</scale>
            <uri>model://abb_irb2600_gazebo_support/meshes/irb2600_12_165/visual/link_2.stl</uri>
          </mesh>
        </geometry>
      </visual>
      <gravity>0</gravity>
      <velocity_decay/>
    </link>
    <joint name='joint_2' type='revolute'>
      <child>link_2</child>
      <parent>link_1</parent>
      <axis>
        <xyz>0 1 0</xyz>
        <limit>
          <lower>-2.705</lower>
          <upper>1.658</upper>
          <effort>0</effort>
          <velocity>3.054</velocity>
        </limit>
        <dynamics>
          <spring_reference>0</spring_reference>
          <spring_stiffness>0</spring_stiffness>
        </dynamics>
      </axis>
    </joint>
    <link name='link_3'>
      <pose>0.15 0 1.145 0 -0 0</pose>
      <inertial>
        <pose>0.04412 0.013987 0.074494 0 -0 0</pose>
        <mass>38</mass>
        <inertia>
          <ixx>0.000293</ixx>
          <ixy>8e-06</ixy>
          <ixz>-1.9e-05</ixz>
          <iyy>0.000399</iyy>
          <iyz>1e-05</iyz>
          <izz>0.000343</izz>
        </inertia>
      </inertial>
      <collision name='link_3_collision'>
        <pose>0 0 0 0 -0 0</pose>
        <geometry>
          <mesh>
            <scale>1 1 1</scale>
            <uri>model://abb_irb2600_gazebo_support/meshes/irb2600_12_165/collision/link_3.stl</uri>
          </mesh>
        </geometry>
        <surface>
          <contact>
            <ode/>
          </contact>
          <friction>
            <ode/>
          </friction>
        </surface>
      </collision>
      <visual name='link_3_visual'>
        <pose>0 0 0 0 -0 0</pose>
        <geometry>
          <mesh>
            <scale>1 1 1</scale>
            <uri>model://abb_irb2600_gazebo_support/meshes/irb2600_12_165/visual/link_3.stl</uri>
          </mesh>
        </geometry>
      </visual>
      <gravity>0</gravity>
      <velocity_decay/>
    </link>
    <joint name='joint_3' type='revolute'>
      <child>link_3</child>
      <parent>link_2</parent>
      <axis>
        <xyz>0 1 0</xyz>
        <limit>
          <lower>-2.705</lower>
          <upper>1.309</upper>
          <effort>0</effort>
          <velocity>3.054</velocity>
        </limit>
        <dynamics>
          <spring_reference>0</spring_reference>
          <spring_stiffness>0</spring_stiffness>
        </dynamics>
      </axis>
    </joint>
    <link name='link_4'>
      <pose>0.15 0 1.26 0 -0 0</pose>
      <inertial>
        <pose>0.604117 0.00122 0.000333 0 -0 0</pose>
        <mass>45</mass>
        <inertia>
          <ixx>1.5e-05</ixx>
          <ixy>-1e-06</ixy>
          <ixz>-0</ixz>
          <iyy>0.000175</iyy>
          <iyz>0</iyz>
          <izz>0.000178</izz>
        </inertia>
      </inertial>
      <collision name='link_4_collision'>
        <pose>0 0 0 0 -0 0</pose>
        <geometry>
          <mesh>
            <scale>1 1 1</scale>
            <uri>model://abb_irb2600_gazebo_support/meshes/irb2600_12_165/collision/link_4.stl</uri>
          </mesh>
        </geometry>
        <surface>
          <contact>
            <ode/>
          </contact>
          <friction>
            <ode/>
          </friction>
        </surface>
      </collision>
      <visual name='link_4_visual'>
        <pose>0 0 0 0 -0 0</pose>
        <geometry>
          <mesh>
            <scale>1 1 1</scale>
            <uri>model://abb_irb2600_gazebo_support/meshes/irb2600_12_165/visual/link_4.stl</uri>
          </mesh>
        </geometry>
      </visual>
      <gravity>0</gravity>
      <velocity_decay/>
    </link>
    <joint name='joint_4' type='revolute'>
      <child>link_4</child>
      <parent>link_3</parent>
      <axis>
        <xyz>1 0 0</xyz>
        <limit>
          <lower>-6.981</lower>
          <upper>6.981</upper>
          <effort>0</effort>
          <velocity>6.283</velocity>
        </limit>
        <dynamics>
          <spring_reference>0</spring_reference>
          <spring_stiffness>0</spring_stiffness>
        </dynamics>
      </axis>
    </joint>
    <link name='link_5'>
      <pose>0.945 0 1.26 0 -0 0</pose>
      <inertial>
        <pose>0.000235 -2.2e-05 0.000891 0 -0 0</pose>
        <mass>6</mass>
        <inertia>
          <ixx>3.1207e-07</ixx>
          <ixy>3.1e-10</ixy>
          <ixz>6.17e-09</ixz>
          <iyy>5.437e-07</iyy>
          <iyz>-2.7e-10</iyz>
          <izz>3.4239e-07</izz>
        </inertia>
      </inertial>
      <collision name='link_5_collision'>
        <pose>0 0 0 0 -0 0</pose>
        <geometry>
          <mesh>
            <scale>1 1 1</scale>
            <uri>model://abb_irb2600_gazebo_support/meshes/irb2600_12_165/collision/link_5.stl</uri>
          </mesh>
        </geometry>
        <surface>
          <contact>
            <ode/>
          </contact>
          <friction>
            <ode/>
          </friction>
        </surface>
      </collision>
      <visual name='link_5_visual'>
        <pose>0 0 0 0 -0 0</pose>
        <geometry>
          <mesh>
            <scale>1 1 1</scale>
            <uri>model://abb_irb2600_gazebo_support/meshes/irb2600_12_165/visual/link_5.stl</uri>
          </mesh>
        </geometry>
      </visual>
      <gravity>0</gravity>
      <velocity_decay/>
    </link>
    <joint name='joint_5' type='revolute'>
      <child>link_5</child>
      <parent>link_4</parent>
      <axis>
        <xyz>0 1 0</xyz>
        <limit>
          <lower>-2.094</lower>
          <upper>2.094</upper>
          <effort>0</effort>
          <velocity>6.283</velocity>
        </limit>
        <dynamics>
          <spring_reference>0</spring_reference>
          <spring_stiffness>0</spring_stiffness>
        </dynamics>
      </axis>
    </joint>
    <link name='link_6'>
      <pose>1.03 0 1.26 0 -0 0</pose>
      <inertial>
        <pose>-0.010849 0.000185 -0.000736 0 -0 0</pose>
        <mass>4</mass>
        <inertia>
          <ixx>1.778e-08</ixx>
          <ixy>-5e-11</ixy>
          <ixz>1.6e-10</ixz>
          <iyy>1.095e-08</iyy>
          <iyz>-1.9e-10</iyz>
          <izz>1.179e-08</izz>
        </inertia>
      </inertial>
      <collision name='link_6_collision'>
        <pose>0 0 0 0 -0 0</pose>
        <geometry>
          <mesh>
            <scale>1 1 1</scale>
            <uri>model://abb_irb2600_gazebo_support/meshes/irb2600_12_165/collision/link_6.stl</uri>
          </mesh>
        </geometry>
        <surface>
          <contact>
            <ode/>
          </contact>
          <friction>
            <ode/>
          </friction>
        </surface>
      </collision>
      <visual name='link_6_visual'>
        <pose>0 0 0 0 -0 0</pose>
        <geometry>
          <mesh>
            <scale>1 1 1</scale>
            <uri>model://abb_irb2600_gazebo_support/meshes/irb2600_12_165/visual/link_6.stl</uri>
          </mesh>
        </geometry>
      </visual>
      <gravity>0</gravity>
      <velocity_decay/>
    </link>
    <joint name='joint_6' type='revolute'>
      <child>link_6</child>
      <parent>link_5</parent>
      <axis>
        <xyz>1 0 0</xyz>
        <limit>
          <lower>-6.981</lower>
          <upper>6.981</upper>
          <effort>0</effort>
          <velocity>8.727</velocity>
        </limit>
        <dynamics>
          <spring_reference>0</spring_reference>
          <spring_stiffness>0</spring_stiffness>
        </dynamics>
      </axis>
    </joint>
    <static>0</static>
    <plugin name='gazebo_ros_control' filename='libgazebo_ros_control.so'>
      <robotNamespace>/</robotNamespace>
      <robotSimType>gazebo_ros_control/DefaultRobotHWSim</robotSimType>
    </plugin>
  </model>
</sdf>
