<?xml version="1.0" encoding="utf-8"?>
<!-- =================================================================================== -->
<!-- |    This document was autogenerated by xacro from workcell.xacro                 | -->
<!-- |    EDITING THIS FILE BY HAND IS NOT RECOMMENDED                                 | -->
<!-- =================================================================================== -->
<robot name="myworkcell">
  <!-- Conversion were obtained from http://www.e-paint.co.uk/Lab_values.asp
       unless otherwise stated. -->
  <link name="grinder_frame">
    <visual>
      <origin rpy="0 3.14159 0" xyz="0 0 0"/>
      <geometry>
        <mesh filename="package://myworkcell_support/meshes/grinder_visual.dae"/>
      </geometry>
    </visual>
    <collision>
      <origin rpy="0 3.14159 0" xyz="0 0 0"/>
      <geometry>
        <mesh filename="package://myworkcell_support/meshes/grinder_collision.dae"/>
      </geometry>
    </collision>
  </link>
  <link name="ee_mount"/>
  <!-- link "ee_base" and connected joints-->
  <link name="ee_base">
    <visual>
      <geometry>
        <mesh filename="package://myworkcell_support/meshes/puzzle_mount.stl"/>
      </geometry>
      &gt;
    
    </visual>
    <collision>
      <geometry>
        <mesh filename="package://myworkcell_support/meshes/puzzle_mount.stl"/>
      </geometry>
    </collision>
  </link>
  <joint name="ee_mount-ee_base" type="fixed">
    <parent link="ee_mount"/>
    <child link="ee_base"/>
    <origin rpy="0 0 0" xyz="0 0 0"/>
  </joint>
  <!-- tool1 is the point that parts connect to the tool -->
  <link name="tool1"/>
  <joint name="ee_base-tool1" type="fixed">
    <parent link="ee_base"/>
    <child link="tool1"/>
    <origin rpy="0.523599 -0.523599 0" xyz="-0.0083 0.0541 0.0143"/>
  </joint>
  <link name="part">
    <visual>
      <geometry>
        <mesh filename="package://myworkcell_support/meshes/puzzle_bent.dae"/>
      </geometry>
    </visual>
    <collision>
      <geometry>
        <mesh filename="package://myworkcell_support/meshes/puzzle_bent.dae"/>
      </geometry>
    </collision>
  </link>
  <joint name="tool1-part" type="fixed">
    <parent link="tool1"/>
    <child link="part"/>
    <origin rpy="0 -0.2618 0" xyz="0.0110 0.0030 -0.0379"/>
  </joint>
  <!-- Links -->
  <link name="world"/>
  <link name="camera_frame"/>
  <!-- links -->
  <link name="base_link">
    <visual>
      <origin rpy="0 0 0" xyz="0 0 0"/>
      <geometry>
        <mesh filename="package://abb_irb2600_support/meshes/irb2600_12_165/visual/base_link.stl"/>
      </geometry>
      <material name="">
        <color rgba="0.7372549 0.3490196 0.1607843 1"/>
      </material>
    </visual>
    <collision>
      <origin rpy="0 0 0" xyz="0 0 0"/>
      <geometry>
        <mesh filename="package://abb_irb2600_support/meshes/irb2600_12_165/collision/base_link.stl"/>
      </geometry>
    </collision>
  </link>
  <link name="link_1">
    <visual>
      <origin rpy="0 0 0" xyz="0 0 0"/>
      <geometry>
        <mesh filename="package://abb_irb2600_support/meshes/irb2600_12_165/visual/link_1.stl"/>
      </geometry>
      <material name="">
        <color rgba="0.7372549 0.3490196 0.1607843 1"/>
      </material>
    </visual>
    <collision>
      <origin rpy="0 0 0" xyz="0 0 0"/>
      <geometry>
        <mesh filename="package://abb_irb2600_support/meshes/irb2600_12_165/collision/link_1.stl"/>
      </geometry>
    </collision>
  </link>
  <link name="link_2">
    <visual>
      <origin rpy="0 0 0" xyz="0 0 0"/>
      <geometry>
        <mesh filename="package://abb_irb2600_support/meshes/irb2600_12_165/visual/link_2.stl"/>
      </geometry>
      <material name="">
        <color rgba="0.7372549 0.3490196 0.1607843 1"/>
      </material>
    </visual>
    <collision>
      <origin rpy="0 0 0" xyz="0 0 0"/>
      <geometry>
        <mesh filename="package://abb_irb2600_support/meshes/irb2600_12_165/collision/link_2.stl"/>
      </geometry>
    </collision>
  </link>
  <link name="link_3">
    <visual>
      <origin rpy="0 0 0" xyz="0 0 0"/>
      <geometry>
        <mesh filename="package://abb_irb2600_support/meshes/irb2600_12_165/visual/link_3.stl"/>
      </geometry>
      <material name="">
        <color rgba="0.7372549 0.3490196 0.1607843 1"/>
      </material>
    </visual>
    <collision>
      <origin rpy="0 0 0" xyz="0 0 0"/>
      <geometry>
        <mesh filename="package://abb_irb2600_support/meshes/irb2600_12_165/collision/link_3.stl"/>
      </geometry>
    </collision>
  </link>
  <link name="link_4">
    <visual>
      <origin rpy="0 0 0" xyz="0 0 0"/>
      <geometry>
        <mesh filename="package://abb_irb2600_support/meshes/irb2600_12_165/visual/link_4.stl"/>
      </geometry>
      <material name="">
        <color rgba="0.7372549 0.3490196 0.1607843 1"/>
      </material>
    </visual>
    <collision>
      <origin rpy="0 0 0" xyz="0 0 0"/>
      <geometry>
        <mesh filename="package://abb_irb2600_support/meshes/irb2600_12_165/collision/link_4.stl"/>
      </geometry>
    </collision>
  </link>
  <link name="link_5">
    <visual>
      <origin rpy="0 0 0" xyz="0 0 0"/>
      <geometry>
        <mesh filename="package://abb_irb2600_support/meshes/irb2600_12_165/visual/link_5.stl"/>
      </geometry>
      <material name="">
        <color rgba="0.7372549 0.3490196 0.1607843 1"/>
      </material>
    </visual>
    <collision>
      <origin rpy="0 0 0" xyz="0 0 0"/>
      <geometry>
        <mesh filename="package://abb_irb2600_support/meshes/irb2600_12_165/collision/link_5.stl"/>
      </geometry>
    </collision>
  </link>
  <link name="link_6">
    <visual>
      <origin rpy="0 0 0" xyz="0 0 0"/>
      <geometry>
        <mesh filename="package://abb_irb2600_support/meshes/irb2600_12_165/visual/link_6.stl"/>
      </geometry>
      <material name="">
        <color rgba="0.5 0.5 0.5 1"/>
      </material>
    </visual>
    <collision>
      <origin rpy="0 0 0" xyz="0 0 0"/>
      <geometry>
        <mesh filename="package://abb_irb2600_support/meshes/irb2600_12_165/collision/link_6.stl"/>
      </geometry>
    </collision>
  </link>
  <link name="tool0"/>
  <!-- Joints -->
  <joint name="joint_1" type="revolute">
    <origin rpy="0 0 0" xyz="0 0 0.445"/>
    <parent link="base_link"/>
    <child link="link_1"/>
    <axis xyz="0 0 1"/>
    <limit effort="0" lower="-3.14159" upper="3.14159" velocity="3.054"/>
  </joint>
  <joint name="joint_2" type="revolute">
    <origin rpy="0 0 0" xyz="0.15 0 0.0"/>
    <parent link="link_1"/>
    <child link="link_2"/>
    <axis xyz="0 1 0"/>
    <limit effort="0" lower="-2.705" upper="1.658" velocity="3.054"/>
  </joint>
  <joint name="joint_3" type="revolute">
    <origin rpy="0 0 0" xyz="0 0 0.7"/>
    <parent link="link_2"/>
    <child link="link_3"/>
    <axis xyz="0 1 0"/>
    <limit effort="0" lower="-2.705" upper="1.309" velocity="3.054"/>
  </joint>
  <joint name="joint_4" type="revolute">
    <origin rpy="0 0 0" xyz="0 0 0.115"/>
    <parent link="link_3"/>
    <child link="link_4"/>
    <axis xyz="1 0 0"/>
    <limit effort="0" lower="-6.981" upper="6.981" velocity="6.283"/>
  </joint>
  <joint name="joint_5" type="revolute">
    <origin rpy="0 0 0" xyz="0.795 0 0 "/>
    <parent link="link_4"/>
    <child link="link_5"/>
    <axis xyz="0 1 0"/>
    <limit effort="0" lower="-2.094" upper="2.094" velocity="6.283"/>
  </joint>
  <joint name="joint_6" type="revolute">
    <origin rpy="0 0 0" xyz="0.085 0 0"/>
    <parent link="link_5"/>
    <child link="link_6"/>
    <axis xyz="1 0 0"/>
    <limit effort="0" lower="-6.981" upper="6.981" velocity="8.727"/>
  </joint>
  <joint name="joint6-tool0" type="fixed">
    <origin rpy="0 1.5707963267948966 0" xyz="0 0 0"/>
    <parent link="link_6"/>
    <child link="tool0"/>
  </joint>
  <!-- ROS base_link to ABB World Coordinates transform -->
  <link name="base"/>
  <joint name="base_link-base" type="fixed">
    <origin rpy="0 0 0" xyz="0 0 0"/>
    <parent link="base_link"/>
    <child link="base"/>
  </joint>
  <!-- <xacro:trispector prefix="" /> -->
  <!-- Joints -->
  <joint name="world_to_camera" type="fixed">
    <parent link="world"/>
    <child link="camera_frame"/>
    <origin rpy="0.0 3.14159 0.0" xyz="-0.25 -0.5 1.25"/>
  </joint>
  <joint name="world_to_robot" type="fixed">
    <parent link="world"/>
    <child link="base_link"/>
    <origin rpy="0.0 0.0 0.0" xyz="0.0 0.0 0.0"/>
  </joint>
  <joint name="world_to_grinder" type="fixed">
    <parent link="world"/>
    <child link="grinder_frame"/>
    <origin rpy="0 3.14159 0" xyz="0.0 -0.4 0.1"/>
  </joint>
  <joint name="tool_to_puzzle" type="fixed">
    <parent link="tool0"/>
    <child link="ee_mount"/>
    <origin rpy="1.5708 0 0" xyz="0 0 0"/>
  </joint>
  <!-- <joint name="robot_to_eff" type="fixed">
    <parent link="tool0" />
    <child link="eff_frame" />
    <origin xyz="0.0 0.0 0.0" rpy="-1.5708 -1.5708 0.0" />
  </joint> -->
</robot>
